2018-02-05 11:28:06,365 INFO: Microblog startup [in /Users/patrickhildreth/Documents/python/flask-microblog/app/__init__.py:47]
2018-02-05 11:31:46,384 INFO: Microblog startup [in /Users/patrickhildreth/Documents/python/flask-microblog/app/__init__.py:47]
2018-02-05 11:32:29,682 INFO: Microblog startup [in /Users/patrickhildreth/Documents/python/flask-microblog/app/__init__.py:47]
2018-02-05 11:33:12,241 INFO: Microblog startup [in /Users/patrickhildreth/Documents/python/flask-microblog/app/__init__.py:47]
2018-02-05 11:33:28,209 INFO: Microblog startup [in /Users/patrickhildreth/Documents/python/flask-microblog/app/__init__.py:47]
2018-02-05 11:44:14,639 INFO: Microblog startup [in /Users/patrickhildreth/Documents/python/flask-microblog/app/__init__.py:47]
2018-02-08 10:59:04,038 INFO: Microblog startup [in /Users/patrickhildreth/Documents/python/flask-microblog/app/__init__.py:47]
2018-02-08 11:14:01,374 INFO: Microblog startup [in /Users/patrickhildreth/Documents/python/flask-microblog/app/__init__.py:47]
2018-02-08 11:14:30,316 ERROR: Exception on /login [POST] [in /Users/patrickhildreth/Documents/python/flask-microblog/venv/lib/python3.6/site-packages/flask/app.py:1560]
Traceback (most recent call last):
  File "/Users/patrickhildreth/Documents/python/flask-microblog/venv/lib/python3.6/site-packages/flask/app.py", line 1982, in wsgi_app
    response = self.full_dispatch_request()
  File "/Users/patrickhildreth/Documents/python/flask-microblog/venv/lib/python3.6/site-packages/flask/app.py", line 1614, in full_dispatch_request
    rv = self.handle_user_exception(e)
  File "/Users/patrickhildreth/Documents/python/flask-microblog/venv/lib/python3.6/site-packages/flask/app.py", line 1517, in handle_user_exception
    reraise(exc_type, exc_value, tb)
  File "/Users/patrickhildreth/Documents/python/flask-microblog/venv/lib/python3.6/site-packages/flask/_compat.py", line 33, in reraise
    raise value
  File "/Users/patrickhildreth/Documents/python/flask-microblog/venv/lib/python3.6/site-packages/flask/app.py", line 1612, in full_dispatch_request
    rv = self.dispatch_request()
  File "/Users/patrickhildreth/Documents/python/flask-microblog/venv/lib/python3.6/site-packages/flask/app.py", line 1598, in dispatch_request
    return self.view_functions[rule.endpoint](**req.view_args)
  File "/Users/patrickhildreth/Documents/python/flask-microblog/app/routes.py", line 54, in login
    if user is None or not user.check_password(form.password.data):
AttributeError: 'User' object has no attribute 'check_password'
2018-02-08 11:16:53,223 INFO: Microblog startup [in /Users/patrickhildreth/Documents/python/flask-microblog/app/__init__.py:47]
2018-02-08 11:17:18,666 INFO: Microblog startup [in /Users/patrickhildreth/Documents/python/flask-microblog/app/__init__.py:47]
2018-02-08 11:17:26,633 ERROR: Exception on /login [POST] [in /Users/patrickhildreth/Documents/python/flask-microblog/venv/lib/python3.6/site-packages/flask/app.py:1560]
Traceback (most recent call last):
  File "/Users/patrickhildreth/Documents/python/flask-microblog/venv/lib/python3.6/site-packages/flask/app.py", line 1982, in wsgi_app
    response = self.full_dispatch_request()
  File "/Users/patrickhildreth/Documents/python/flask-microblog/venv/lib/python3.6/site-packages/flask/app.py", line 1614, in full_dispatch_request
    rv = self.handle_user_exception(e)
  File "/Users/patrickhildreth/Documents/python/flask-microblog/venv/lib/python3.6/site-packages/flask/app.py", line 1517, in handle_user_exception
    reraise(exc_type, exc_value, tb)
  File "/Users/patrickhildreth/Documents/python/flask-microblog/venv/lib/python3.6/site-packages/flask/_compat.py", line 33, in reraise
    raise value
  File "/Users/patrickhildreth/Documents/python/flask-microblog/venv/lib/python3.6/site-packages/flask/app.py", line 1612, in full_dispatch_request
    rv = self.dispatch_request()
  File "/Users/patrickhildreth/Documents/python/flask-microblog/venv/lib/python3.6/site-packages/flask/app.py", line 1598, in dispatch_request
    return self.view_functions[rule.endpoint](**req.view_args)
  File "/Users/patrickhildreth/Documents/python/flask-microblog/app/routes.py", line 54, in login
    if user is None or not user.check_password(form.password.data):
AttributeError: 'User' object has no attribute 'check_password'
2018-02-08 11:17:41,553 INFO: Microblog startup [in /Users/patrickhildreth/Documents/python/flask-microblog/app/__init__.py:47]
2018-02-08 11:17:45,618 INFO: Microblog startup [in /Users/patrickhildreth/Documents/python/flask-microblog/app/__init__.py:47]
2018-02-08 11:17:51,450 ERROR: Exception on /login [POST] [in /Users/patrickhildreth/Documents/python/flask-microblog/venv/lib/python3.6/site-packages/flask/app.py:1560]
Traceback (most recent call last):
  File "/Users/patrickhildreth/Documents/python/flask-microblog/venv/lib/python3.6/site-packages/flask/app.py", line 1982, in wsgi_app
    response = self.full_dispatch_request()
  File "/Users/patrickhildreth/Documents/python/flask-microblog/venv/lib/python3.6/site-packages/flask/app.py", line 1614, in full_dispatch_request
    rv = self.handle_user_exception(e)
  File "/Users/patrickhildreth/Documents/python/flask-microblog/venv/lib/python3.6/site-packages/flask/app.py", line 1517, in handle_user_exception
    reraise(exc_type, exc_value, tb)
  File "/Users/patrickhildreth/Documents/python/flask-microblog/venv/lib/python3.6/site-packages/flask/_compat.py", line 33, in reraise
    raise value
  File "/Users/patrickhildreth/Documents/python/flask-microblog/venv/lib/python3.6/site-packages/flask/app.py", line 1612, in full_dispatch_request
    rv = self.dispatch_request()
  File "/Users/patrickhildreth/Documents/python/flask-microblog/venv/lib/python3.6/site-packages/flask/app.py", line 1598, in dispatch_request
    return self.view_functions[rule.endpoint](**req.view_args)
  File "/Users/patrickhildreth/Documents/python/flask-microblog/app/routes.py", line 58, in login
    next_page = request.args.get('next')
NameError: name 'request' is not defined
2018-02-08 11:20:02,995 ERROR: Exception on /index [GET] [in /Users/patrickhildreth/Documents/python/flask-microblog/venv/lib/python3.6/site-packages/flask/app.py:1560]
Traceback (most recent call last):
  File "/Users/patrickhildreth/Documents/python/flask-microblog/venv/lib/python3.6/site-packages/flask/app.py", line 1982, in wsgi_app
    response = self.full_dispatch_request()
  File "/Users/patrickhildreth/Documents/python/flask-microblog/venv/lib/python3.6/site-packages/flask/app.py", line 1614, in full_dispatch_request
    rv = self.handle_user_exception(e)
  File "/Users/patrickhildreth/Documents/python/flask-microblog/venv/lib/python3.6/site-packages/flask/app.py", line 1517, in handle_user_exception
    reraise(exc_type, exc_value, tb)
  File "/Users/patrickhildreth/Documents/python/flask-microblog/venv/lib/python3.6/site-packages/flask/_compat.py", line 33, in reraise
    raise value
  File "/Users/patrickhildreth/Documents/python/flask-microblog/venv/lib/python3.6/site-packages/flask/app.py", line 1612, in full_dispatch_request
    rv = self.dispatch_request()
  File "/Users/patrickhildreth/Documents/python/flask-microblog/venv/lib/python3.6/site-packages/flask/app.py", line 1598, in dispatch_request
    return self.view_functions[rule.endpoint](**req.view_args)
  File "/Users/patrickhildreth/Documents/python/flask-microblog/venv/lib/python3.6/site-packages/flask_login/utils.py", line 261, in decorated_view
    return func(*args, **kwargs)
  File "/Users/patrickhildreth/Documents/python/flask-microblog/app/routes.py", line 42, in index
    return redirect(url_for('index'))
  File "/Users/patrickhildreth/Documents/python/flask-microblog/app/models.py", line 57, in followed_posts
    followers.follower_id == self.id)
AttributeError: 'Table' object has no attribute 'follower_id'
2018-02-08 11:20:06,011 ERROR: Exception on /index [GET] [in /Users/patrickhildreth/Documents/python/flask-microblog/venv/lib/python3.6/site-packages/flask/app.py:1560]
Traceback (most recent call last):
  File "/Users/patrickhildreth/Documents/python/flask-microblog/venv/lib/python3.6/site-packages/flask/app.py", line 1982, in wsgi_app
    response = self.full_dispatch_request()
  File "/Users/patrickhildreth/Documents/python/flask-microblog/venv/lib/python3.6/site-packages/flask/app.py", line 1614, in full_dispatch_request
    rv = self.handle_user_exception(e)
  File "/Users/patrickhildreth/Documents/python/flask-microblog/venv/lib/python3.6/site-packages/flask/app.py", line 1517, in handle_user_exception
    reraise(exc_type, exc_value, tb)
  File "/Users/patrickhildreth/Documents/python/flask-microblog/venv/lib/python3.6/site-packages/flask/_compat.py", line 33, in reraise
    raise value
  File "/Users/patrickhildreth/Documents/python/flask-microblog/venv/lib/python3.6/site-packages/flask/app.py", line 1612, in full_dispatch_request
    rv = self.dispatch_request()
  File "/Users/patrickhildreth/Documents/python/flask-microblog/venv/lib/python3.6/site-packages/flask/app.py", line 1598, in dispatch_request
    return self.view_functions[rule.endpoint](**req.view_args)
  File "/Users/patrickhildreth/Documents/python/flask-microblog/venv/lib/python3.6/site-packages/flask_login/utils.py", line 261, in decorated_view
    return func(*args, **kwargs)
  File "/Users/patrickhildreth/Documents/python/flask-microblog/app/routes.py", line 42, in index
    return redirect(url_for('index'))
  File "/Users/patrickhildreth/Documents/python/flask-microblog/app/models.py", line 57, in followed_posts
    followers.follower_id == self.id)
AttributeError: 'Table' object has no attribute 'follower_id'
