2018-02-08 11:22:34,731 ERROR: Exception on /login [GET] [in /Users/patrickhildreth/Documents/python/flask-microblog/venv/lib/python3.6/site-packages/flask/app.py:1560]
Traceback (most recent call last):
  File "/Users/patrickhildreth/Documents/python/flask-microblog/venv/lib/python3.6/site-packages/flask/app.py", line 1982, in wsgi_app
    response = self.full_dispatch_request()
  File "/Users/patrickhildreth/Documents/python/flask-microblog/venv/lib/python3.6/site-packages/flask/app.py", line 1614, in full_dispatch_request
    rv = self.handle_user_exception(e)
  File "/Users/patrickhildreth/Documents/python/flask-microblog/venv/lib/python3.6/site-packages/flask/app.py", line 1517, in handle_user_exception
    reraise(exc_type, exc_value, tb)
  File "/Users/patrickhildreth/Documents/python/flask-microblog/venv/lib/python3.6/site-packages/flask/_compat.py", line 33, in reraise
    raise value
  File "/Users/patrickhildreth/Documents/python/flask-microblog/venv/lib/python3.6/site-packages/flask/app.py", line 1610, in full_dispatch_request
    rv = self.preprocess_request()
  File "/Users/patrickhildreth/Documents/python/flask-microblog/venv/lib/python3.6/site-packages/flask/app.py", line 1831, in preprocess_request
    rv = func()
  File "/Users/patrickhildreth/Documents/python/flask-microblog/app/routes.py", line 30, in before_request
    db.session.commit()
NameError: name 'db' is not defined
2018-02-08 11:22:35,310 ERROR: Exception on /favicon.ico [GET] [in /Users/patrickhildreth/Documents/python/flask-microblog/venv/lib/python3.6/site-packages/flask/app.py:1560]
Traceback (most recent call last):
  File "/Users/patrickhildreth/Documents/python/flask-microblog/venv/lib/python3.6/site-packages/flask/app.py", line 1982, in wsgi_app
    response = self.full_dispatch_request()
  File "/Users/patrickhildreth/Documents/python/flask-microblog/venv/lib/python3.6/site-packages/flask/app.py", line 1614, in full_dispatch_request
    rv = self.handle_user_exception(e)
  File "/Users/patrickhildreth/Documents/python/flask-microblog/venv/lib/python3.6/site-packages/flask/app.py", line 1517, in handle_user_exception
    reraise(exc_type, exc_value, tb)
  File "/Users/patrickhildreth/Documents/python/flask-microblog/venv/lib/python3.6/site-packages/flask/_compat.py", line 33, in reraise
    raise value
  File "/Users/patrickhildreth/Documents/python/flask-microblog/venv/lib/python3.6/site-packages/flask/app.py", line 1610, in full_dispatch_request
    rv = self.preprocess_request()
  File "/Users/patrickhildreth/Documents/python/flask-microblog/venv/lib/python3.6/site-packages/flask/app.py", line 1831, in preprocess_request
    rv = func()
  File "/Users/patrickhildreth/Documents/python/flask-microblog/app/routes.py", line 30, in before_request
    db.session.commit()
NameError: name 'db' is not defined
2018-02-08 11:22:36,547 ERROR: Exception on /index [GET] [in /Users/patrickhildreth/Documents/python/flask-microblog/venv/lib/python3.6/site-packages/flask/app.py:1560]
Traceback (most recent call last):
  File "/Users/patrickhildreth/Documents/python/flask-microblog/venv/lib/python3.6/site-packages/flask/app.py", line 1982, in wsgi_app
    response = self.full_dispatch_request()
  File "/Users/patrickhildreth/Documents/python/flask-microblog/venv/lib/python3.6/site-packages/flask/app.py", line 1614, in full_dispatch_request
    rv = self.handle_user_exception(e)
  File "/Users/patrickhildreth/Documents/python/flask-microblog/venv/lib/python3.6/site-packages/flask/app.py", line 1517, in handle_user_exception
    reraise(exc_type, exc_value, tb)
  File "/Users/patrickhildreth/Documents/python/flask-microblog/venv/lib/python3.6/site-packages/flask/_compat.py", line 33, in reraise
    raise value
  File "/Users/patrickhildreth/Documents/python/flask-microblog/venv/lib/python3.6/site-packages/flask/app.py", line 1610, in full_dispatch_request
    rv = self.preprocess_request()
  File "/Users/patrickhildreth/Documents/python/flask-microblog/venv/lib/python3.6/site-packages/flask/app.py", line 1831, in preprocess_request
    rv = func()
  File "/Users/patrickhildreth/Documents/python/flask-microblog/app/routes.py", line 30, in before_request
    db.session.commit()
NameError: name 'db' is not defined
2018-02-08 11:22:37,007 ERROR: Exception on /favicon.ico [GET] [in /Users/patrickhildreth/Documents/python/flask-microblog/venv/lib/python3.6/site-packages/flask/app.py:1560]
Traceback (most recent call last):
  File "/Users/patrickhildreth/Documents/python/flask-microblog/venv/lib/python3.6/site-packages/flask/app.py", line 1982, in wsgi_app
    response = self.full_dispatch_request()
  File "/Users/patrickhildreth/Documents/python/flask-microblog/venv/lib/python3.6/site-packages/flask/app.py", line 1614, in full_dispatch_request
    rv = self.handle_user_exception(e)
  File "/Users/patrickhildreth/Documents/python/flask-microblog/venv/lib/python3.6/site-packages/flask/app.py", line 1517, in handle_user_exception
    reraise(exc_type, exc_value, tb)
  File "/Users/patrickhildreth/Documents/python/flask-microblog/venv/lib/python3.6/site-packages/flask/_compat.py", line 33, in reraise
    raise value
  File "/Users/patrickhildreth/Documents/python/flask-microblog/venv/lib/python3.6/site-packages/flask/app.py", line 1610, in full_dispatch_request
    rv = self.preprocess_request()
  File "/Users/patrickhildreth/Documents/python/flask-microblog/venv/lib/python3.6/site-packages/flask/app.py", line 1831, in preprocess_request
    rv = func()
  File "/Users/patrickhildreth/Documents/python/flask-microblog/app/routes.py", line 30, in before_request
    db.session.commit()
NameError: name 'db' is not defined
2018-02-08 11:22:37,990 ERROR: Exception on /logout [GET] [in /Users/patrickhildreth/Documents/python/flask-microblog/venv/lib/python3.6/site-packages/flask/app.py:1560]
Traceback (most recent call last):
  File "/Users/patrickhildreth/Documents/python/flask-microblog/venv/lib/python3.6/site-packages/flask/app.py", line 1982, in wsgi_app
    response = self.full_dispatch_request()
  File "/Users/patrickhildreth/Documents/python/flask-microblog/venv/lib/python3.6/site-packages/flask/app.py", line 1614, in full_dispatch_request
    rv = self.handle_user_exception(e)
  File "/Users/patrickhildreth/Documents/python/flask-microblog/venv/lib/python3.6/site-packages/flask/app.py", line 1517, in handle_user_exception
    reraise(exc_type, exc_value, tb)
  File "/Users/patrickhildreth/Documents/python/flask-microblog/venv/lib/python3.6/site-packages/flask/_compat.py", line 33, in reraise
    raise value
  File "/Users/patrickhildreth/Documents/python/flask-microblog/venv/lib/python3.6/site-packages/flask/app.py", line 1610, in full_dispatch_request
    rv = self.preprocess_request()
  File "/Users/patrickhildreth/Documents/python/flask-microblog/venv/lib/python3.6/site-packages/flask/app.py", line 1831, in preprocess_request
    rv = func()
  File "/Users/patrickhildreth/Documents/python/flask-microblog/app/routes.py", line 30, in before_request
    db.session.commit()
NameError: name 'db' is not defined
2018-02-08 11:22:38,430 ERROR: Exception on /favicon.ico [GET] [in /Users/patrickhildreth/Documents/python/flask-microblog/venv/lib/python3.6/site-packages/flask/app.py:1560]
Traceback (most recent call last):
  File "/Users/patrickhildreth/Documents/python/flask-microblog/venv/lib/python3.6/site-packages/flask/app.py", line 1982, in wsgi_app
    response = self.full_dispatch_request()
  File "/Users/patrickhildreth/Documents/python/flask-microblog/venv/lib/python3.6/site-packages/flask/app.py", line 1614, in full_dispatch_request
    rv = self.handle_user_exception(e)
  File "/Users/patrickhildreth/Documents/python/flask-microblog/venv/lib/python3.6/site-packages/flask/app.py", line 1517, in handle_user_exception
    reraise(exc_type, exc_value, tb)
  File "/Users/patrickhildreth/Documents/python/flask-microblog/venv/lib/python3.6/site-packages/flask/_compat.py", line 33, in reraise
    raise value
  File "/Users/patrickhildreth/Documents/python/flask-microblog/venv/lib/python3.6/site-packages/flask/app.py", line 1610, in full_dispatch_request
    rv = self.preprocess_request()
  File "/Users/patrickhildreth/Documents/python/flask-microblog/venv/lib/python3.6/site-packages/flask/app.py", line 1831, in preprocess_request
    rv = func()
  File "/Users/patrickhildreth/Documents/python/flask-microblog/app/routes.py", line 30, in before_request
    db.session.commit()
NameError: name 'db' is not defined
2018-02-08 11:22:40,668 ERROR: Exception on /logout [GET] [in /Users/patrickhildreth/Documents/python/flask-microblog/venv/lib/python3.6/site-packages/flask/app.py:1560]
Traceback (most recent call last):
  File "/Users/patrickhildreth/Documents/python/flask-microblog/venv/lib/python3.6/site-packages/flask/app.py", line 1982, in wsgi_app
    response = self.full_dispatch_request()
  File "/Users/patrickhildreth/Documents/python/flask-microblog/venv/lib/python3.6/site-packages/flask/app.py", line 1614, in full_dispatch_request
    rv = self.handle_user_exception(e)
  File "/Users/patrickhildreth/Documents/python/flask-microblog/venv/lib/python3.6/site-packages/flask/app.py", line 1517, in handle_user_exception
    reraise(exc_type, exc_value, tb)
  File "/Users/patrickhildreth/Documents/python/flask-microblog/venv/lib/python3.6/site-packages/flask/_compat.py", line 33, in reraise
    raise value
  File "/Users/patrickhildreth/Documents/python/flask-microblog/venv/lib/python3.6/site-packages/flask/app.py", line 1610, in full_dispatch_request
    rv = self.preprocess_request()
  File "/Users/patrickhildreth/Documents/python/flask-microblog/venv/lib/python3.6/site-packages/flask/app.py", line 1831, in preprocess_request
    rv = func()
  File "/Users/patrickhildreth/Documents/python/flask-microblog/app/routes.py", line 30, in before_request
    db.session.commit()
NameError: name 'db' is not defined
2018-02-08 11:22:50,973 INFO: Microblog startup [in /Users/patrickhildreth/Documents/python/flask-microblog/app/__init__.py:47]
